<?xml version="1.0" encoding="utf-8"?>
<!-- This URDF was automatically created by SolidWorks to URDF Exporter! Originally created by Stephen Brawner (brawner@gmail.com) 
     Commit Version: 1.6.0-1-g15f4949  Build Version: 1.6.7594.29634
     For more information, please see http://wiki.ros.org/sw_urdf_exporter -->
<robot
  name="tnbd">

  <link name="base_footprint"/>

  <joint name="base_joint" type="fixed">
    <parent link="base_footprint"/>
    <child link="base_link" />
    <origin xyz="0.0118828123771107 -0.0151599566389232 0.0203146741285486" rpy="0 0 0"/>
  </joint>

  <link
    name="base_link">
    <inertial>
      <origin
        xyz="0.0118828123771107 -0.0151599566389232 0.0203146741285486"
        rpy="0 0 0" />
      <mass
        value="3.82951363180605" />
      <inertia
        ixx="0.00953722660979492"
        ixy="4.41781425832141E-05"
        ixz="-0.000341208625610832"
        iyy="0.0158761844988063"
        iyz="0.00016579675323455"
        izz="0.00924032898116037" />
    </inertial>
    <visual>
      <origin
        xyz="0 0 0"
        rpy="0 0 0" />
      <geometry>
        <mesh
          filename="package://tnbd/meshes/base_link.STL" />
      </geometry>
      <material
        name="">
        <color
          rgba="0.792156862745098 0.819607843137255 0.933333333333333 1" />
      </material>
    </visual>
    <collision>
      <origin
        xyz="0 0 0"
        rpy="0 0 0" />
      <geometry>
        <mesh
          filename="package://tnbd/meshes/base_link.STL" />
      </geometry>
    </collision>
  </link>
  <link
    name="imu_link">
    <inertial>
      <origin
        xyz="-0.0148711338289682 0.0225700856602626 -0.0105521904971602"
        rpy="0 0 0" />
      <mass
        value="5.39050020671944" />
      <inertia
        ixx="0.0660269478366575"
        ixy="0.00165660880666066"
        ixz="0.000691738225942454"
        iyy="0.0516312097649989"
        iyz="-0.000432909278582528"
        izz="0.0830303357844912" />
    </inertial>
    <visual>
      <origin
        xyz="0 0 0"
        rpy="0 0 0" />
      <geometry>
        <mesh
          filename="package://tnbd/meshes/imu_link.STL" />
      </geometry>
      <material
        name="">
        <color
          rgba="0.792156862745098 0.819607843137255 0.933333333333333 1" />
      </material>
    </visual>
    <collision>
      <origin
        xyz="0 0 0"
        rpy="0 0 0" />
      <geometry>
        <mesh
          filename="package://tnbd/meshes/imu_link.STL" />
      </geometry>
    </collision>
  </link>
  <joint
    name="imu_joint"
    type="fixed">
    <origin
      xyz="0 0 0"
      rpy="0 0 -3.1416" />
    <parent
      link="base_link" />
    <child
      link="imu_link" />
    <axis
      xyz="0 0 0" />
  </joint>
  <link
    name="base_scan">
    <inertial>
      <origin
        xyz="1.33939688298779E-08 1.11156737980789E-09 0.0293857857356863"
        rpy="0 0 0" />
      <mass
        value="0.131767415545665" />
      <inertia
        ixx="6.95670084224573E-05"
        ixy="-9.59372993171304E-12"
        ixz="-5.29717288318515E-11"
        iyy="6.95671229244128E-05"
        iyz="-4.39613134808164E-12"
        izz="4.47644343972088E-05" />
    </inertial>
    <visual>
      <origin
        xyz="0 0 0"
        rpy="0 0 0" />
      <geometry>
        <mesh
          filename="package://tnbd/meshes/base_scan.STL" />
      </geometry>
      <material
        name="">
        <color
          rgba="0.792156862745098 0.819607843137255 0.933333333333333 1" />
      </material>
    </visual>
    <collision>
      <origin
        xyz="0 0 0"
        rpy="0 0 0" />
      <geometry>
        <mesh
          filename="package://tnbd/meshes/base_scan.STL" />
      </geometry>
    </collision>
  </link>
  <joint
    name="scan_joint"
    type="fixed">
    <origin
      xyz="0.033457 -0.012168 0.08"
      rpy="0 0 0" />
    <parent
      link="base_link" />
    <child
      link="base_scan" />
    <axis
      xyz="0 0 0" />
  </joint>
  <link
    name="camera_link">
    <inertial>
      <origin
        xyz="-6.93889390390723E-17 -2.45868853054887E-10 0.0165"
        rpy="0 0 0" />
      <mass
        value="0.166876325452904" />
      <inertia
        ixx="2.72223823415769E-05"
        ixy="-2.58754254803585E-19"
        ixz="-3.93505911224222E-19"
        iyy="0.000412109193003404"
        iyz="4.56820459567891E-14"
        izz="0.000409043522275279" />
    </inertial>
    <visual>
      <origin
        xyz="0 0 0"
        rpy="0 0 0" />
      <geometry>
        <mesh
          filename="package://tnbd/meshes/camera_link.STL" />
      </geometry>
      <material
        name="">
        <color
          rgba="0.792156862745098 0.819607843137255 0.933333333333333 1" />
      </material>
    </visual>
    <collision>
      <origin
        xyz="0 0 0"
        rpy="0 0 0" />
      <geometry>
        <mesh
          filename="package://tnbd/meshes/camera_link.STL" />
      </geometry>
    </collision>
  </link>
  <joint
    name="camera_joint"
    type="fixed">
    <origin
      xyz="0.16546 -0.012168 0.095"
      rpy="-1.5708 0 1.5708" />
    <parent
      link="base_link" />
    <child
      link="camera_link" />
    <axis
      xyz="0 0 0" />
  </joint>
  <link
    name="wheel_left_link">
    <inertial>
      <origin
        xyz="-4.5102810375397E-17 -9.0205620750794E-17 0.0145"
        rpy="0 0 0" />
      <mass
        value="0.431849530870227" />
      <inertia
        ixx="0.000547310482911071"
        ixy="2.71050543121376E-20"
        ixz="-1.81452362622999E-19"
        iyy="0.000547310482911071"
        iyz="-1.28725864655537E-19"
        izz="0.00103898710950625" />
    </inertial>
    <visual>
      <origin
        xyz="0 0 0"
        rpy="0 0 0" />
      <geometry>
        <mesh
          filename="package://tnbd/meshes/wheel_left_link.STL" />
      </geometry>
      <material
        name="">
        <color
          rgba="0.792156862745098 0.819607843137255 0.933333333333333 1" />
      </material>
    </visual>
    <collision>
      <origin
        xyz="0 0 0"
        rpy="0 0 0" />
      <geometry>
        <mesh
          filename="package://tnbd/meshes/wheel_left_link.STL" />
      </geometry>
    </collision>
  </link>
  <joint
    name="wheel_left_joint"
    type="continuous">
    <origin
      xyz="-0.029043 0.11763 -0.0309"
      rpy="-1.5708 0.22977 0" />
    <parent
      link="base_link" />
    <child
      link="wheel_left_link" />
    <axis
      xyz="0 0 1" />
  </joint>
  <link
    name="wheel_right_link">
    <inertial>
      <origin
        xyz="0 0 0.0145"
        rpy="0 0 0" />
      <mass
        value="0.431849530870227" />
      <inertia
        ixx="0.000547310482911071"
        ixy="-2.71050543121376E-20"
        ixz="-1.394926709703E-19"
        iyy="0.000547310482911071"
        iyz="-7.78691293765183E-20"
        izz="0.00103898710950625" />
    </inertial>
    <visual>
      <origin
        xyz="0 0 0"
        rpy="0 0 0" />
      <geometry>
        <mesh
          filename="package://tnbd/meshes/wheel_right_link.STL" />
      </geometry>
      <material
        name="">
        <color
          rgba="0.792156862745098 0.819607843137255 0.933333333333333 1" />
      </material>
    </visual>
    <collision>
      <origin
        xyz="0 0 0"
        rpy="0 0 0" />
      <geometry>
        <mesh
          filename="package://tnbd/meshes/wheel_right_link.STL" />
      </geometry>
    </collision>
  </link>
  <joint
    name="wheel_right_joint"
    type="continuous">
    <origin
      xyz="-0.029043 -0.14197 -0.0309"
      rpy="-1.5708 -1.1484 3.1416" />
    <parent
      link="base_link" />
    <child
      link="wheel_right_link" />
    <axis
      xyz="0 0 1" />
  </joint>
  <link
    name="front_link">
    <inertial>
      <origin
        xyz="-0.106387398730393 -0.0241722425834856 -0.0475102012708915"
        rpy="0 0 0" />
      <mass
        value="0.273534418315026" />
      <inertia
        ixx="0.000334043672794129"
        ixy="6.52325344689438E-07"
        ixz="1.2821362483546E-06"
        iyy="0.000727701941790312"
        iyz="-0.000125647714472025"
        izz="0.000619074079142028" />
    </inertial>
    <visual>
      <origin
        xyz="0 0 0"
        rpy="0 0 0" />
      <geometry>
        <mesh
          filename="package://tnbd/meshes/front_link.STL" />
      </geometry>
      <material
        name="">
        <color
          rgba="0.792156862745098 0.819607843137255 0.933333333333333 1" />
      </material>
    </visual>
    <collision>
      <origin
        xyz="0 0 0"
        rpy="0 0 0" />
      <geometry>
        <mesh
          filename="package://tnbd/meshes/front_link.STL" />
      </geometry>
    </collision>
  </link>
  <joint
    name="front_joint"
    type="revolute">
    <origin
      xyz="0.15446 0 -0.057"
      rpy="-2.7277 0 1.5708" />
    <parent
      link="base_link" />
    <child
      link="front_link" />
    <axis
      xyz="1 0 0" />
    <limit
      lower="0"
      upper="2.000321"
      effort="0"
      velocity="0" />
  </joint>
  <link
    name="feed_link">
    <inertial>
      <origin
        xyz="-0.0165698438786785 1.15879528195251E-15 0.000750000000000042"
        rpy="0 0 0" />
      <mass
        value="0.00143426215563702" />
      <inertia
        ixx="5.89380670397773E-08"
        ixy="4.92131105438424E-21"
        ixz="6.10747572651202E-22"
        iyy="2.65747442341082E-07"
        iyz="-1.76577131822209E-20"
        izz="3.24147661072495E-07" />
    </inertial>
    <visual>
      <origin
        xyz="0 0 0"
        rpy="0 0 0" />
      <geometry>
        <mesh
          filename="package://tnbd/meshes/feed_link.STL" />
      </geometry>
      <material
        name="">
        <color
          rgba="0.792156862745098 0.819607843137255 0.933333333333333 1" />
      </material>
    </visual>
    <collision>
      <origin
        xyz="0 0 0"
        rpy="0 0 0" />
      <geometry>
        <mesh
          filename="package://tnbd/meshes/feed_link.STL" />
      </geometry>
    </collision>
  </link>
  <joint
    name="feed_joint"
    type="revolute">
    <origin
      xyz="-0.057043 0.049832 0.0513"
      rpy="0 0 1.5635" />
    <parent
      link="base_link" />
    <child
      link="feed_link" />
    <axis
      xyz="0 0 1" />
    <limit
      lower="-0.802851"
      upper="0"
      effort="0"
      velocity="0" />
  </joint>
  <link
    name="back_link">
    <inertial>
      <origin
        xyz="-0.00543276816529464 -0.000916138436977992 -0.0453101770351191"
        rpy="0 0 0" />
      <mass
        value="0.123674446484502" />
      <inertia
        ixx="0.000154119408139331"
        ixy="-8.33579496985985E-08"
        ixz="-4.11070369647792E-06"
        iyy="0.000392855091836655"
        iyz="-7.8928663261899E-06"
        izz="0.000263524969170412" />
    </inertial>
    <visual>
      <origin
        xyz="0 0 0"
        rpy="0 0 0" />
      <geometry>
        <mesh
          filename="package://tnbd/meshes/back_link.STL" />
      </geometry>
      <material
        name="">
        <color
          rgba="0.792156862745098 0.819607843137255 0.933333333333333 1" />
      </material>
    </visual>
    <collision>
      <origin
        xyz="0 0 0"
        rpy="0 0 0" />
      <geometry>
        <mesh
          filename="package://tnbd/meshes/back_link.STL" />
      </geometry>
    </collision>
  </link>
  <joint
    name="back_joint"
    type="revolute">
    <origin
      xyz="-0.087043 0 -0.057"
      rpy="-3.1392 0 1.5708" />
    <parent
      link="base_link" />
    <child
      link="back_link" />
    <axis
      xyz="1 0 0" />
    <limit
      lower="-1.570796"
      upper="0"
      effort="0"
      velocity="0" />
  </joint>
</robot>